Traceback (most recent call last):
  File "/opt/conda/lib/python3.9/site-packages/jupyter_cache/executors/utils.py", line 51, in single_nb_execution
    executenb(
  File "/opt/conda/lib/python3.9/site-packages/nbclient/client.py", line 1204, in execute
    return NotebookClient(nb=nb, resources=resources, km=km, **kwargs).execute()
  File "/opt/conda/lib/python3.9/site-packages/nbclient/util.py", line 84, in wrapped
    return just_run(coro(*args, **kwargs))
  File "/opt/conda/lib/python3.9/site-packages/nbclient/util.py", line 62, in just_run
    return loop.run_until_complete(coro)
  File "/opt/conda/lib/python3.9/asyncio/base_events.py", line 647, in run_until_complete
    return future.result()
  File "/opt/conda/lib/python3.9/site-packages/nbclient/client.py", line 663, in async_execute
    await self.async_execute_cell(
  File "/opt/conda/lib/python3.9/site-packages/nbclient/client.py", line 965, in async_execute_cell
    await self._check_raise_for_error(cell, cell_index, exec_reply)
  File "/opt/conda/lib/python3.9/site-packages/nbclient/client.py", line 862, in _check_raise_for_error
    raise CellExecutionError.from_cell_and_msg(cell, exec_reply_content)
nbclient.exceptions.CellExecutionError: An error occurred while executing the following cell:
------------------
from sklearn.linear_model import Ridge, Lasso
from sklearn.pipeline import make_pipeline
from sklearn.preprocessing import StandardScaler

model = Lasso(alpha=100)
model.fit(X_train.values[:100,:], np.log(y_train)[:100,])
------------------

[0;31m---------------------------------------------------------------------------[0m
[0;31mNameError[0m                                 Traceback (most recent call last)
Cell [0;32mIn [36], line 6[0m
[1;32m      3[0m [38;5;28;01mfrom[39;00m [38;5;21;01msklearn[39;00m[38;5;21;01m.[39;00m[38;5;21;01mpreprocessing[39;00m [38;5;28;01mimport[39;00m StandardScaler
[1;32m      5[0m model [38;5;241m=[39m Lasso(alpha[38;5;241m=[39m[38;5;241m100[39m)
[0;32m----> 6[0m model[38;5;241m.[39mfit(X_train[38;5;241m.[39mvalues[:[38;5;241m100[39m,:], np[38;5;241m.[39mlog(y_train)[:[38;5;241m100[39m,])

[0;31mNameError[0m: name 'np' is not defined
NameError: name 'np' is not defined

